Workbook

Sheet Monitor
A1: Sector_1_dígito | B1: id | C1: Nombre | D1: saldo_total (miles de $) | E1: saldo_irregular (miles de $) | F1: tasa_mora
A2: Otros | B2: 0 | C2: NaN | D2: 63116287592 | E2: 6959703931 | F2: =E2/D2 -> 0.11026795
A3: Agricultura, ganadería y silvicultura | B3: 11 | C3: Cultivos temporales | D3: 6371444007 | E3: 170218901 | F3: =E3/D3 -> 0.026715906
A4: Agricultura, ganadería y silvicultura | B4: 12 | C4: Cultivos perennes | D4: 614846765 | E4: 20850754 | F4: =E4/D4 -> 0.033912115
A5: Agricultura, ganadería y silvicultura | B5: 13 | C5: Producción de semillas y de otras formas de propagación de cultivos agrícolas | D5: 610383932 | E5: 9400985 | F5: =E5/D5 -> 0.015401757
A6: Agricultura, ganadería y silvicultura | B6: 14 | C6: Cría de animales | D6: 2749446461 | E6: 69794707 | F6: =E6/D6 -> 0.025385003
A7: Agricultura, ganadería y silvicultura | B7: 16 | C7: Servicios de apoyo agrícolas y pecuarios | D7: 1165449821 | E7: 60071354 | F7: =E7/D7 -> 0.051543492
A8: Agricultura, ganadería y silvicultura | B8: 17 | C8: Caza, repoblación de animales de caza y servicios de apoyo | D8: 3678420 | E8: 25830 | F8: =E8/D8 -> 0.0070220366
A9: Agricultura, ganadería y silvicultura | B9: 21 | C9: Silvicultura | D9: 4208637 | E9: 314580 | F9: =E9/D9 -> 0.07474629
A10: Agricultura, ganadería y silvicultura | B10: 22 | C10: Extracción de productos forestales | D10: 35427340 | E10: 4393447 | F10: =E10/D10 -> 0.1240129
A11: Agricultura, ganadería y silvicultura | B11: 24 | C11: Servicios de apoyo a la silvicultura | D11: 11819269 | E11: 89795 | F11: =E11/D11 -> 0.0075973396
A12: Pesca | B12: 31 | C12: Pesca y servicios de apoyo | D12: 91202133 | E12: 4130327 | F12: =E12/D12 -> 0.045287614
A13: Pesca | B13: 32 | C13: Explotación de criaderos de peces, granjas piscícolas y otros frutos acuáticos (acuicultura) | D13: 10738332 | E13: 367750 | F13: =E13/D13 -> 0.034246473
... A226: Otras actividades de servicios comunitarios, sociales y personales | B226: 999 | C226: Otros sectores | D226: 498297839 | E226: 55440768 | F226: =E226/D226 -> 0.1112603
A227: Otros | B227: nan | C227: nan | D227: 13948320352 | E227: 3410208077 | F227: =E227/D227 -> 0.2444888

Sheet Output - 3 dígitos
A1: Sector_1_dígito | B1: id | C1: Nombre | D1: Nombre_ok | E1: saldo_total (miles de $) | F1: saldo_irregular (miles de $) | G1: tasa_mora
A2: Otros | B2: 0 | C2: NaN | D2: =SUBSTITUTE(SUBSTITUTE(SUBSTITUTE(SUBSTITUTE(SUBSTITUTE(SUBSTITUTE(SUBSTITUTE(C2,"Ã¡","á"),"Ã©","é"),"Ã­","í"),"Ã³","ó"),"Ãº","ú"),"Ã±","ñ"),"Ã","í") -> NaN | E2: =SUMIF(INPUT!$A$2:$A$396,'Output - 3 dígitos'!B2,INPUT!$B$2:$B$396) -> 63116287592 | F2: =SUMIF(INPUT!$A$2:$A$396,'Output - 3 dígitos'!B2,INPUT!$C$2:$C$396) -> 6959703931 | G2: =F2/E2 -> 0.11026795 | J2: {=_xlfn.SORTBY($D$2:$D$227,$G$2:$G$227,-1)} -> Fabricación y reparación de locomotoras y de material rodante para transporte ferroviario | K2: {=_xlfn._xlws.SORT(G2:G228,,-1)} -> 0.52717339
A3: Agricultura, ganadería y silvicultura | B3: 11 | C3: Cultivos temporales | D3: =SUBSTITUTE(SUBSTITUTE(SUBSTITUTE(SUBSTITUTE(SUBSTITUTE(SUBSTITUTE(SUBSTITUTE(C3,"Ã¡","á"),"Ã©","é"),"Ã­","í"),"Ã³","ó"),"Ãº","ú"),"Ã±","ñ"),"Ã","í") -> Cultivos temporales | E3: =SUMIF(INPUT!$A$2:$A$396,'Output - 3 dígitos'!B3,INPUT!$B$2:$B$396) -> 6371444007 | F3: =SUMIF(INPUT!$A$2:$A$396,'Output - 3 dígitos'!B3,INPUT!$C$2:$C$396) -> 170218901 | G3: =F3/E3 -> 0.026715906 | J3: Curtido y terminación de cueros | K3: 0.36562047
A4: Agricultura, ganadería y silvicultura | B4: 12 | C4: Cultivos perennes | D4: =SUBSTITUTE(SUBSTITUTE(SUBSTITUTE(SUBSTITUTE(SUBSTITUTE(SUBSTITUTE(SUBSTITUTE(C4,"Ã¡","á"),"Ã©","é"),"Ã­","í"),"Ã³","ó"),"Ãº","ú"),"Ã±","ñ"),"Ã","í") -> Cultivos perennes | E4: =SUMIF(INPUT!$A$2:$A$396,'Output - 3 dígitos'!B4,INPUT!$B$2:$B$396) -> 614846765 | F4: =SUMIF(INPUT!$A$2:$A$396,'Output - 3 dígitos'!B4,INPUT!$C$2:$C$396) -> 20850754 | G4: =F4/E4 -> 0.033912115 | J4: Elaboración de productos de molinería, almidones y productos derivados del almidón | K4: 0.26368787
A5: Agricultura, ganadería y silvicultura | B5: 13 | C5: ProducciÃ³n de semillas y de otras formas de propagaciÃ³n de cultivos agrÃ­colas | D5: =SUBSTITUTE(SUBSTITUTE(SUBSTITUTE(SUBSTITUTE(SUBSTITUTE(SUBSTITUTE(SUBSTITUTE(C5,"Ã¡","á"),"Ã©","é"),"Ã­","í"),"Ã³","ó"),"Ãº","ú"),"Ã±","ñ"),"Ã","í") -> Producción de semillas y de otras formas de propagación de cultivos agrícolas | E5: =SUMIF(INPUT!$A$2:$A$396,'Output - 3 dígitos'!B5,INPUT!$B$2:$B$396) -> 610383932 | F5: =SUMIF(INPUT!$A$2:$A$396,'Output - 3 dígitos'!B5,INPUT!$C$2:$C$396) -> 9400985 | G5: =F5/E5 -> 0.015401757 | J5: nan | K5: 0.2444888
A6: Agricultura, ganadería y silvicultura | B6: 14 | C6: CrÃ­a de animales | D6: =SUBSTITUTE(SUBSTITUTE(SUBSTITUTE(SUBSTITUTE(SUBSTITUTE(SUBSTITUTE(SUBSTITUTE(C6,"Ã¡","á"),"Ã©","é"),"Ã­","í"),"Ã³","ó"),"Ãº","ú"),"Ã±","ñ"),"Ã","í") -> Cría de animales | E6: =SUMIF(INPUT!$A$2:$A$396,'Output - 3 dígitos'!B6,INPUT!$B$2:$B$396) -> 2749446461 | F6: =SUMIF(INPUT!$A$2:$A$396,'Output - 3 dígitos'!B6,INPUT!$C$2:$C$396) -> 69794707 | G6: =F6/E6 -> 0.025385003 | J6: Servicios industriales para la industria confeccionista | K6: 0.20056906
A7: Agricultura, ganadería y silvicultura | B7: 16 | C7: Servicios de apoyo agrÃ­colas y pecuarios | D7: =SUBSTITUTE(SUBSTITUTE(SUBSTITUTE(SUBSTITUTE(SUBSTITUTE(SUBSTITUTE(SUBSTITUTE(C7,"Ã¡","á"),"Ã©","é"),"Ã­","í"),"Ã³","ó"),"Ãº","ú"),"Ã±","ñ"),"Ã","í") -> Servicios de apoyo agrícolas y pecuarios | E7: =SUMIF(INPUT!$A$2:$A$396,'Output - 3 dígitos'!B7,INPUT!$B$2:$B$396) -> 1165449821 | F7: =SUMIF(INPUT!$A$2:$A$396,'Output - 3 dígitos'!B7,INPUT!$C$2:$C$396) -> 60071354 | G7: =F7/E7 -> 0.051543492 | J7: Fabricación de fibras manufacturadas | K7: 0.17370316
A8: Agricultura, ganadería y silvicultura | B8: 17 | C8: Caza, repoblaciÃ³n de animales de caza y servicios de apoyo | D8: =SUBSTITUTE(SUBSTITUTE(SUBSTITUTE(SUBSTITUTE(SUBSTITUTE(SUBSTITUTE(SUBSTITUTE(C8,"Ã¡","á"),"Ã©","é"),"Ã­","í"),"Ã³","ó"),"Ãº","ú"),"Ã±","ñ"),"Ã","í") -> Caza, repoblación de animales de caza y servicios de apoyo | E8: =SUMIF(INPUT!$A$2:$A$396,'Output - 3 dígitos'!B8,INPUT!$B$2:$B$396) -> 3678420 | F8: =SUMIF(INPUT!$A$2:$A$396,'Output - 3 dígitos'!B8,INPUT!$C$2:$C$396) -> 25830 | G8: =F8/E8 -> 0.0070220366 | J8: Fabricación de motores, generadores y transformadores eléctricos y aparatos de distribución y control de la energía eléctrica | K8: 0.13377607
A9: Agricultura, ganadería y silvicultura | B9: 21 | C9: Silvicultura | D9: =SUBSTITUTE(SUBSTITUTE(SUBSTITUTE(SUBSTITUTE(SUBSTITUTE(SUBSTITUTE(SUBSTITUTE(C9,"Ã¡","á"),"Ã©","é"),"Ã­","í"),"Ã³","ó"),"Ãº","ú"),"Ã±","ñ"),"Ã","í") -> Silvicultura | E9: =SUMIF(INPUT!$A$2:$A$396,'Output - 3 dígitos'!B9,INPUT!$B$2:$B$396) -> 4208637 | F9: =SUMIF(INPUT!$A$2:$A$396,'Output - 3 dígitos'!B9,INPUT!$C$2:$C$396) -> 314580 | G9: =F9/E9 -> 0.07474629 | J9: Servicios de la seguridad social obligatoria, excepto obras sociales | K9: 0.13007137
A10: Agricultura, ganadería y silvicultura | B10: 22 | C10: ExtracciÃ³n de productos forestales | D10: =SUBSTITUTE(SUBSTITUTE(SUBSTITUTE(SUBSTITUTE(SUBSTITUTE(SUBSTITUTE(SUBSTITUTE(C10,"Ã¡","á"),"Ã©","é"),"Ã­","í"),"Ã³","ó"),"Ãº","ú"),"Ã±","ñ"),"Ã","í") -> Extracción de productos forestales | E10: =SUMIF(INPUT!$A$2:$A$396,'Output - 3 dígitos'!B10,INPUT!$B$2:$B$396) -> 35427340 | F10: =SUMIF(INPUT!$A$2:$A$396,'Output - 3 dígitos'!B10,INPUT!$C$2:$C$396) -> 4393447 | G10: =F10/E10 -> 0.1240129 | J10: Extracción de productos forestales | K10: 0.1240129
A11: Agricultura, ganadería y silvicultura | B11: 24 | C11: Servicios de apoyo a la silvicultura | D11: =SUBSTITUTE(SUBSTITUTE(SUBSTITUTE(SUBSTITUTE(SUBSTITUTE(SUBSTITUTE(SUBSTITUTE(C11,"Ã¡","á"),"Ã©","é"),"Ã­","í"),"Ã³","ó"),"Ãº","ú"),"Ã±","ñ"),"Ã","í") -> Servicios de apoyo a la silvicultura | E11: =SUMIF(INPUT!$A$2:$A$396,'Output - 3 dígitos'!B11,INPUT!$B$2:$B$396) -> 11819269 | F11: =SUMIF(INPUT!$A$2:$A$396,'Output - 3 dígitos'!B11,INPUT!$C$2:$C$396) -> 89795 | G11: =F11/E11 -> 0.0075973396 | J11: Servicios de manipulación de cargas | K11: 0.1203414
A12: Pesca | B12: 31 | C12: Pesca y servicios de apoyo | D12: =SUBSTITUTE(SUBSTITUTE(SUBSTITUTE(SUBSTITUTE(SUBSTITUTE(SUBSTITUTE(SUBSTITUTE(C12,"Ã¡","á"),"Ã©","é"),"Ã­","í"),"Ã³","ó"),"Ãº","ú"),"Ã±","ñ"),"Ã","í") -> Pesca y servicios de apoyo | E12: =SUMIF(INPUT!$A$2:$A$396,'Output - 3 dígitos'!B12,INPUT!$B$2:$B$396) -> 91202133 | F12: =SUMIF(INPUT!$A$2:$A$396,'Output - 3 dígitos'!B12,INPUT!$C$2:$C$396) -> 4130327 | G12: =F12/E12 -> 0.045287614 | J12: Fabricación de papel y de productos de papel | K12: 0.11826732
A13: Pesca | B13: 32 | C13: ExplotaciÃ³n de criaderos de peces, granjas piscÃ­colas y otros frutos acuÃ¡ticos (acuicultura) | D13: =SUBSTITUTE(SUBSTITUTE(SUBSTITUTE(SUBSTITUTE(SUBSTITUTE(SUBSTITUTE(SUBSTITUTE(C13,"Ã¡","á"),"Ã©","é"),"Ã­","í"),"Ã³","ó"),"Ãº","ú"),"Ã±","ñ"),"Ã","í") -> Explotación de criaderos de peces, granjas piscícolas y otros frutos acuáticos (acuicultura) | E13: =SUMIF(INPUT!$A$2:$A$396,'Output - 3 dígitos'!B13,INPUT!$B$2:$B$396) -> 10738332 | F13: =SUMIF(INPUT!$A$2:$A$396,'Output - 3 dígitos'!B13,INPUT!$C$2:$C$396) -> 367750 | G13: =F13/E13 -> 0.034246473 | J13: Elaboración de pescado y productos de pescado | K13: 0.11514531
A14: Minería, petróleo y gas | B14: 51 | C14: ExtracciÃ³n y aglomeraciÃ³n de carbÃ³n | D14: =SUBSTITUTE(SUBSTITUTE(SUBSTITUTE(SUBSTITUTE(SUBSTITUTE(SUBSTITUTE(SUBSTITUTE(C14,"Ã¡","á"),"Ã©","é"),"Ã­","í"),"Ã³","ó"),"Ãº","ú"),"Ã±","ñ"),"Ã","í") -> Extracción y aglomeración de carbón | E14: =SUMIF(INPUT!$A$2:$A$396,'Output - 3 dígitos'!B14,INPUT!$B$2:$B$396) -> 804004 | F14: =SUMIF(INPUT!$A$2:$A$396,'Output - 3 dígitos'!B14,INPUT!$C$2:$C$396) -> 3456 | G14: =F14/E14 -> 0.0042984861 | J14: Venta al por menor de productos alimenticios, bebidas y tabaco en comercios especializados | K14: 0.11500953
... A226: Otras actividades de servicios comunitarios, sociales y personales | B226: 999 | C226: Otros sectores | D226: =SUBSTITUTE(SUBSTITUTE(SUBSTITUTE(SUBSTITUTE(SUBSTITUTE(SUBSTITUTE(SUBSTITUTE(C226,"Ã¡","á"),"Ã©","é"),"Ã­","í"),"Ã³","ó"),"Ãº","ú"),"Ã±","ñ"),"Ã","í") -> Otros sectores | E226: =SUMIF(INPUT!$A$2:$A$396,'Output - 3 dígitos'!B226,INPUT!$B$2:$B$396) -> 498297839 | F226: =SUMIF(INPUT!$A$2:$A$396,'Output - 3 dígitos'!B226,INPUT!$C$2:$C$396) -> 55440768 | G226: =F226/E226 -> 0.1112603 | J226: Terminación y teñido de pieles | K226: 0
A227: Otros | B227: nan | C227: nan | D227: =SUBSTITUTE(SUBSTITUTE(SUBSTITUTE(SUBSTITUTE(SUBSTITUTE(SUBSTITUTE(SUBSTITUTE(C227,"Ã¡","á"),"Ã©","é"),"Ã­","í"),"Ã³","ó"),"Ãº","ú"),"Ã±","ñ"),"Ã","í") -> nan | E227: =SUMIF(INPUT!$A$2:$A$396,'Output - 3 dígitos'!B227,INPUT!$B$2:$B$396) -> 13948320352 | F227: =SUMIF(INPUT!$A$2:$A$396,'Output - 3 dígitos'!B227,INPUT!$C$2:$C$396) -> 3410208077 | G227: =F227/E227 -> 0.2444888 | J227: Fabricación de armas y municiones | K227: 0
K228: 0

Sheet Output - 1 díg
B1: Saldo Total | C1: Saldo Irregularidad | D1: Tasa
A2: Agricultura, ganadería y silvicultura | B2: =SUMIF('Output - 3 dígitos'!$A$2:$A$227,'Output - 1 díg'!$A2,'Output - 3 dígitos'!E$2:E$227) -> 11566704652 | C2: =SUMIF('Output - 3 dígitos'!$A$2:$A$227,'Output - 1 díg'!$A2,'Output - 3 dígitos'!F$2:F$227) -> 335160353 | D2: =C2/B2 -> 0.028976304
A3: Pesca | B3: =SUMIF('Output - 3 dígitos'!$A$2:$A$227,'Output - 1 díg'!$A3,'Output - 3 dígitos'!E$2:E$227) -> 101940465 | C3: =SUMIF('Output - 3 dígitos'!$A$2:$A$227,'Output - 1 díg'!$A3,'Output - 3 dígitos'!F$2:F$227) -> 4498077 | D3: =C3/B3 -> 0.044124549
A4: Minería, petróleo y gas | B4: =SUMIF('Output - 3 dígitos'!$A$2:$A$227,'Output - 1 díg'!$A4,'Output - 3 dígitos'!E$2:E$227) -> 5486700877 | C4: =SUMIF('Output - 3 dígitos'!$A$2:$A$227,'Output - 1 díg'!$A4,'Output - 3 dígitos'!F$2:F$227) -> 20481756 | D4: =C4/B4 -> 0.0037329821
A5: Industria | B5: =SUM(B6:B18) -> 24200989321 | C5: =SUM(C6:C18) -> 710759417 | D5: =C5/B5 -> 0.029369023
A6: Alimentos y bebidas | B6: =SUMIF('Output - 3 dígitos'!$A$2:$A$227,'Output - 1 díg'!$A6,'Output - 3 dígitos'!E$2:E$227) -> 7951192937 | C6: =SUMIF('Output - 3 dígitos'!$A$2:$A$227,'Output - 1 díg'!$A6,'Output - 3 dígitos'!F$2:F$227) -> 299059314 | D6: =C6/B6 -> 0.03761188
A7: Productos del tabaco | B7: =SUMIF('Output - 3 dígitos'!$A$2:$A$227,'Output - 1 díg'!$A7,'Output - 3 dígitos'!E$2:E$227) -> 158569706 | C7: =SUMIF('Output - 3 dígitos'!$A$2:$A$227,'Output - 1 díg'!$A7,'Output - 3 dígitos'!F$2:F$227) -> 697902 | D7: =C7/B7 -> 0.0044012316
A8: Textil, indumentaria, calzado y cuero | B8: =SUMIF('Output - 3 dígitos'!$A$2:$A$227,'Output - 1 díg'!$A8,'Output - 3 dígitos'!E$2:E$227) -> 937308047 | C8: =SUMIF('Output - 3 dígitos'!$A$2:$A$227,'Output - 1 díg'!$A8,'Output - 3 dígitos'!F$2:F$227) -> 93192770 | D8: =C8/B8 -> 0.099425979
A9: Madera, papel y cartón | B9: =SUMIF('Output - 3 dígitos'!$A$2:$A$227,'Output - 1 díg'!$A9,'Output - 3 dígitos'!E$2:E$227) -> 595111760 | C9: =SUMIF('Output - 3 dígitos'!$A$2:$A$227,'Output - 1 díg'!$A9,'Output - 3 dígitos'!F$2:F$227) -> 52542821 | D9: =C9/B9 -> 0.088290678
A10: Edición e Impresión | B10: =SUMIF('Output - 3 dígitos'!$A$2:$A$227,'Output - 1 díg'!$A10,'Output - 3 dígitos'!E$2:E$227) -> 111731403 | C10: =SUMIF('Output - 3 dígitos'!$A$2:$A$227,'Output - 1 díg'!$A10,'Output - 3 dígitos'!F$2:F$227) -> 10430927 | D10: =C10/B10 -> 0.093357165
A11: Refinación del Petróleo | B11: =SUMIF('Output - 3 dígitos'!$A$2:$A$227,'Output - 1 díg'!$A11,'Output - 3 dígitos'!E$2:E$227) -> 2669200214 | C11: =SUMIF('Output - 3 dígitos'!$A$2:$A$227,'Output - 1 díg'!$A11,'Output - 3 dígitos'!F$2:F$227) -> 37363468 | D11: =C11/B11 -> 0.013998001
A12: Sustancias y productos químicos | B12: =SUMIF('Output - 3 dígitos'!$A$2:$A$227,'Output - 1 díg'!$A12,'Output - 3 dígitos'!E$2:E$227) -> 3124541699 | C12: =SUMIF('Output - 3 dígitos'!$A$2:$A$227,'Output - 1 díg'!$A12,'Output - 3 dígitos'!F$2:F$227) -> 116671681 | D12: =C12/B12 -> 0.037340414
A13: Caucho y plástico | B13: =SUMIF('Output - 3 dígitos'!$A$2:$A$227,'Output - 1 díg'!$A13,'Output - 3 dígitos'!E$2:E$227) -> 494725637 | C13: =SUMIF('Output - 3 dígitos'!$A$2:$A$227,'Output - 1 díg'!$A13,'Output - 3 dígitos'!F$2:F$227) -> 10154272 | D13: =C13/B13 -> 0.020525057
A14: Minerales no metálicos | B14: =SUMIF('Output - 3 dígitos'!$A$2:$A$227,'Output - 1 díg'!$A14,'Output - 3 dígitos'!E$2:E$227) -> 647012561 | C14: =SUMIF('Output - 3 dígitos'!$A$2:$A$227,'Output - 1 díg'!$A14,'Output - 3 dígitos'!F$2:F$227) -> 26818295 | D14: =C14/B14 -> 0.041449419
A15: Metales básicos | B15: =SUMIF('Output - 3 dígitos'!$A$2:$A$227,'Output - 1 díg'!$A15,'Output - 3 dígitos'!E$2:E$227) -> 840633405 | C15: =SUMIF('Output - 3 dígitos'!$A$2:$A$227,'Output - 1 díg'!$A15,'Output - 3 dígitos'!F$2:F$227) -> 3793467 | D15: =C15/B15 -> 0.0045126294
A16: Metalmecánica y electrónicos | B16: =SUMIF('Output - 3 dígitos'!$A$2:$A$227,'Output - 1 díg'!$A16,'Output - 3 dígitos'!E$2:E$227) -> 3263432489 | C16: =SUMIF('Output - 3 dígitos'!$A$2:$A$227,'Output - 1 díg'!$A16,'Output - 3 dígitos'!F$2:F$227) -> 35487085 | D16: =C16/B16 -> 0.010874159
A17: Automotores y autopartes | B17: =SUMIF('Output - 3 dígitos'!$A$2:$A$227,'Output - 1 díg'!$A17,'Output - 3 dígitos'!E$2:E$227) -> 2832160933 | C17: =SUMIF('Output - 3 dígitos'!$A$2:$A$227,'Output - 1 díg'!$A17,'Output - 3 dígitos'!F$2:F$227) -> 4948522 | D17: =C17/B17 -> 0.0017472602
... A29: Otros | B29: =SUMIF('Output - 3 dígitos'!$A$2:$A$227,'Output - 1 díg'!$A29,'Output - 3 dígitos'!E$2:E$227) -> 77064607944 | C29: =SUMIF('Output - 3 dígitos'!$A$2:$A$227,'Output - 1 díg'!$A29,'Output - 3 dígitos'!F$2:F$227) -> 10369912008 | D29: =C29/B29 -> 0.13456128
A30: Chequeo | B30: =SUM(B2:B29) -> 183175442941 | C30: =SUM(C2:C29) -> 13207224146 | D30: =C30/B30 -> 0.0721015
B31: =SUM('Output - 3 dígitos'!E2:E227) -> 158974453620 | C31: =SUM('Output - 3 dígitos'!F2:F227) -> 12496464729 | D31: =C31/B31 -> 0.078606747

Sheet Industria - 2 díg
D1: ='Output - 3 dígitos'!E1 -> saldo_total (miles de $) | E1: ='Output - 3 dígitos'!F1 -> saldo_irregular (miles de $) | F1: ='Output - 3 dígitos'!G1 -> tasa_mora | I1: Sectores Industriales - Morosidad | J1: Tasa | K1: Monto (M de u$S)
A2: ='Output - 3 dígitos'!B24 -> 101 | B2: ='Output - 3 dígitos'!C24 -> ProducciÃ³n y procesamiento de carne y productos cÃ¡rnicos, excepto pescado | C2: Producción y procesamiento de carne y productos cárnicos, excepto pescado | D2: ='Output - 3 dígitos'!E24 -> 2898265826 | E2: ='Output - 3 dígitos'!F24 -> 64587255 | F2: ='Output - 3 dígitos'!G24 -> 0.022284793 | H2: 1 | I2: {=_xlfn.SORTBY($C$2:$C$227,$F$2:$F$227,-1)} -> Fabricación y reparación de locomotoras y de material rodante para transporte ferroviario | J2: {=_xlfn._xlws.SORT(F2:F228,,-1)} -> 0.52717339 | K2: {=_xlfn.SORTBY($E$2:$E$227,$F$2:$F$227,-1)/1000/1450} -> 0.30782345
A3: ='Output - 3 dígitos'!B25 -> 102 | B3: ='Output - 3 dígitos'!C25 -> ElaboraciÃ³n de pescado y productos de pescado | C3: Elaboración de pescado y productos de pescado | D3: ='Output - 3 dígitos'!E25 -> 113009710 | E3: ='Output - 3 dígitos'!F25 -> 13012538 | F3: ='Output - 3 dígitos'!G25 -> 0.11514531 | H3: 2 | I3: Curtido y terminación de cueros | J3: 0.36562047 | K3: 26.823341
A4: ='Output - 3 dígitos'!B26 -> 103 | B4: ='Output - 3 dígitos'!C26 -> PreparaciÃ³n de frutas, hortalizas y legumbres | C4: Preparación de frutas, hortalizas y legumbres | D4: ='Output - 3 dígitos'!E26 -> 531783040 | E4: ='Output - 3 dígitos'!F26 -> 762272 | F4: ='Output - 3 dígitos'!G26 -> 0.0014334267 | H4: 3 | I4: Elaboración de productos de molinería, almidones y productos derivados del almidón | J4: 0.26368787 | K4: 79.959304
A5: ='Output - 3 dígitos'!B27 -> 104 | B5: ='Output - 3 dígitos'!C27 -> ElaboraciÃ³n de aceites y grasas de origen vegetal | C5: Elaboración de aceites y grasas de origen vegetal | D5: ='Output - 3 dígitos'!E27 -> 737628041 | E5: ='Output - 3 dígitos'!F27 -> 15529989 | F5: ='Output - 3 dígitos'!G27 -> 0.021053957 | H5: 4 | I5: Servicios industriales para la industria confeccionista | J5: 0.20056906 | K5: 0.38561103
A6: ='Output - 3 dígitos'!B28 -> 105 | B6: ='Output - 3 dígitos'!C28 -> ElaboraciÃ³n de productos lÃ¡cteos | C6: Elaboración de productos lácteos | D6: ='Output - 3 dígitos'!E28 -> 558833881 | E6: ='Output - 3 dígitos'!F28 -> 8141839 | F6: ='Output - 3 dígitos'!G28 -> 0.014569337 | H6: 5 | I6: Fabricación de fibras manufacturadas | J6: 0.17370316 | K6: 0.86630414
A7: ='Output - 3 dígitos'!B29 -> 106 | B7: ='Output - 3 dígitos'!C29 -> ElaboraciÃ³n de productos de molinerÃ­a, almidones y productos derivados del almidÃ³n | C7: Elaboración de productos de molinería, almidones y productos derivados del almidón | D7: ='Output - 3 dígitos'!E29 -> 439690264 | E7: ='Output - 3 dígitos'!F29 -> 115940991 | F7: ='Output - 3 dígitos'!G29 -> 0.26368787 | H7: 6 | I7: Fabricación de motores, generadores y transformadores eléctricos y aparatos de distribución y control de la energía eléctrica | J7: 0.13377607 | K7: 6.0147607
A8: ='Output - 3 dígitos'!B30 -> 107 | B8: ='Output - 3 dígitos'!C30 -> ElaboraciÃ³n de productos alimenticios ncp | C8: Elaboración de productos alimenticios ncp | D8: ='Output - 3 dígitos'!E30 -> 1679981503 | E8: ='Output - 3 dígitos'!F30 -> 17926750 | F8: ='Output - 3 dígitos'!G30 -> 0.010670802 | H8: 7 | I8: Fabricación de papel y de productos de papel | J8: 0.11826732 | K8: 29.797614
A9: ='Output - 3 dígitos'!B31 -> 108 | B9: ='Output - 3 dígitos'!C31 -> ElaboraciÃ³n de alimentos preparados para animales | C9: Elaboración de alimentos preparados para animales | D9: ='Output - 3 dígitos'!E31 -> 164970776 | E9: ='Output - 3 dígitos'!F31 -> 12485335 | F9: ='Output - 3 dígitos'!G31 -> 0.075682101 | H9: 8 | I9: Elaboración de pescado y productos de pescado | J9: 0.11514531 | K9: 8.9741641
A10: ='Output - 3 dígitos'!B32 -> 109 | B10: ='Output - 3 dígitos'!C32 -> Servicios industriales para la elaboraciÃ³n de alimentos y bebidas | C10: Servicios industriales para la elaboración de alimentos y bebidas | D10: ='Output - 3 dígitos'!E32 -> 3491345 | E10: ='Output - 3 dígitos'!F32 -> 104630 | F10: ='Output - 3 dígitos'!G32 -> 0.029968393 | H10: 9 | I10: Impresión y servicios relacionados con la impresión | J10: 0.094885403 | K10: 7.1866193
A11: ='Output - 3 dígitos'!B33 -> 110 | B11: ='Output - 3 dígitos'!C33 -> ElaboraciÃ³n de bebidas | C11: Elaboración de bebidas | D11: ='Output - 3 dígitos'!E33 -> 823538551 | E11: ='Output - 3 dígitos'!F33 -> 50567715 | F11: ='Output - 3 dígitos'!G33 -> 0.061402973 | H11: 10 | I11: Fabricación de acumuladores, pilas y baterías primarias | J11: 0.088294596 | K11: 2.0478317
A12: ='Output - 3 dígitos'!B34 -> 120 | B12: ='Output - 3 dígitos'!C34 -> ElaboraciÃ³n de productos de tabaco | C12: Elaboración de productos de tabaco | D12: ='Output - 3 dígitos'!E34 -> 158569706 | E12: ='Output - 3 dígitos'!F34 -> 697902 | F12: ='Output - 3 dígitos'!G34 -> 0.0044012316 | H12: 11 | I12: Fabricación de productos de hornos de coque | J12: 0.087021045 | K12: 1.6902669
A13: ='Output - 3 dígitos'!B35 -> 131 | B13: ='Output - 3 dígitos'!C35 -> FabricaciÃ³n de hilados y tejidos, acabado de productos textiles | C13: Fabricación de hilados y tejidos, acabado de productos textiles | D13: ='Output - 3 dígitos'!E35 -> 270588005 | E13: ='Output - 3 dígitos'!F35 -> 15277393 | F13: ='Output - 3 dígitos'!G35 -> 0.056459979 | H13: 12 | I13: Fabricación de muebles y colchones | J13: 0.084100286 | K13: 8.5378903
A14: ='Output - 3 dígitos'!B36 -> 139 | B14: ='Output - 3 dígitos'!C36 -> FabricaciÃ³n de productos textiles ncp | C14: Fabricación de productos textiles ncp | D14: ='Output - 3 dígitos'!E36 -> 216850528 | E14: ='Output - 3 dígitos'!F36 -> 14345041 | F14: ='Output - 3 dígitos'!G36 -> 0.066151746 | H14: 13 | I14: Fabricación de joyas, bijouterie y artículos conexos | J14: 0.08018186 | K14: 0.026429655
... A26: ='Output - 3 dígitos'!B48 -> 191 | B26: ='Output - 3 dígitos'!C48 -> FabricaciÃ³n de productos de hornos de coque | C26: Fabricación de productos de hornos de coque | D26: ='Output - 3 dígitos'!E48 -> 28164302 | E26: ='Output - 3 dígitos'!F48 -> 2450887 | F26: ='Output - 3 dígitos'!G48 -> 0.087021045 | H26: 25 | I26: Fabricación de productos minerales no metálicos ncp | J26: 0.04318727 | K26: 17.174739
A27: ='Output - 3 dígitos'!B49 -> 192 | B27: ='Output - 3 dígitos'!C49 -> FabricaciÃ³n de productos de la refinaciÃ³n del petrÃ³leo | C27: Fabricación de productos de la refinación del petróleo | D27: ='Output - 3 dígitos'!E49 -> 2641035912 | E27: ='Output - 3 dígitos'!F49 -> 34912581 | F27: ='Output - 3 dígitos'!G49 -> 0.013219275 | I27: Fabricación de artículos de deporte | J27: 0.041517094 | K27: 0.1156469
A28: ='Output - 3 dígitos'!B50 -> 201 | B28: ='Output - 3 dígitos'!C50 -> FabricaciÃ³n de sustancias quÃ­micas bÃ¡sicas | C28: Fabricación de sustancias químicas básicas | D28: ='Output - 3 dígitos'!E50 -> 908216901 | E28: ='Output - 3 dígitos'!F50 -> 18650123 | F28: ='Output - 3 dígitos'!G50 -> 0.020534878 | I28: Fabricación de productos metálicos para uso estructural, tanques, depósitos y generadores de vapor | J28: 0.035321511 | K28: 3.4109262
A29: ='Output - 3 dígitos'!B51 -> 202 | B29: ='Output - 3 dígitos'!C51 -> FabricaciÃ³n de productos quÃ­micos ncp | C29: Fabricación de productos químicos ncp | D29: ='Output - 3 dígitos'!E51 -> 1211326450 | E29: ='Output - 3 dígitos'!F51 -> 65656314 | F29: ='Output - 3 dígitos'!G51 -> 0.054201998 | I29: Fabricación de productos farmaceúticos, sustancias químicas medicinales y productos botánicos de uso farmaceútico | J29: 0.031351094 | K29: 21.446819
A30: ='Output - 3 dígitos'!B52 -> 203 | B30: ='Output - 3 dígitos'!C52 -> FabricaciÃ³n de fibras manufacturadas | C30: Fabricación de fibras manufacturadas | D30: ='Output - 3 dígitos'!E52 -> 7231538 | E30: ='Output - 3 dígitos'!F52 -> 1256141 | F30: ='Output - 3 dígitos'!G52 -> 0.17370316 | I30: Servicios industriales para la elaboración de alimentos y bebidas | J30: 0.029968393 | K30: 0.072158621
A31: ='Output - 3 dígitos'!B53 -> 204 | B31: ='Output - 3 dígitos'!C53 -> Servicios industriales para la fabricaciÃ³n de sustancias y productos quÃ­micos | C31: Servicios industriales para la fabricación de sustancias y productos químicos | D31: ='Output - 3 dígitos'!E53 -> 5843317 | E31: ='Output - 3 dígitos'!F53 -> 11216 | F31: ='Output - 3 dígitos'!G53 -> 0.0019194577 | I31: Fabricación de vidrio y productos de vidrio | J31: 0.027210007 | K31: 1.3206366
A32: ='Output - 3 dígitos'!B54 -> 210 | B32: ='Output - 3 dígitos'!C54 -> FabricaciÃ³n de productos farmaceÃºticos, sustancias quÃ­micas medicinales y productos botÃ¡nicos de uso farmaceÃºtico | C32: Fabricación de productos farmaceúticos, sustancias químicas medicinales y productos botánicos de uso farmaceútico | D32: ='Output - 3 dígitos'!E54 -> 991923493 | E32: ='Output - 3 dígitos'!F54 -> 31097887 | F32: ='Output - 3 dígitos'!G54 -> 0.031351094 | I32: Fabricación de productos de caucho | J32: 0.026525251 | K32: 1.1581221
A33: ='Output - 3 dígitos'!B55 -> 221 | B33: ='Output - 3 dígitos'!C55 -> FabricaciÃ³n de productos de caucho | C33: Fabricación de productos de caucho | D33: ='Output - 3 dígitos'!E55 -> 63308619 | E33: ='Output - 3 dígitos'!F55 -> 1679277 | F33: ='Output - 3 dígitos'!G55 -> 0.026525251 | I33: Producción y procesamiento de carne y productos cárnicos, excepto pescado | J33: 0.022284793 | K33: 44.542934
A34: ='Output - 3 dígitos'!B56 -> 222 | B34: ='Output - 3 dígitos'!C56 -> FabricaciÃ³n de productos de plÃ¡stico | C34: Fabricación de productos de plástico | D34: ='Output - 3 dígitos'!E56 -> 431417018 | E34: ='Output - 3 dígitos'!F56 -> 8474995 | F34: ='Output - 3 dígitos'!G56 -> 0.019644554 | I34: Elaboración de aceites y grasas de origen vegetal | J34: 0.021053957 | K34: 10.710337
A35: ='Output - 3 dígitos'!B57 -> 231 | B35: ='Output - 3 dígitos'!C57 -> FabricaciÃ³n de vidrio y productos de vidrio | C35: Fabricación de vidrio y productos de vidrio | D35: ='Output - 3 dígitos'!E57 -> 70375690 | E35: ='Output - 3 dígitos'!F57 -> 1914923 | F35: ='Output - 3 dígitos'!G57 -> 0.027210007 | I35: Fabricación de sustancias químicas básicas | J35: 0.020534878 | K35: 12.862154
A36: ='Output - 3 dígitos'!B58 -> 239 | B36: ='Output - 3 dígitos'!C58 -> FabricaciÃ³n de productos minerales no metÃ¡licos ncp | C36: Fabricación de productos minerales no metálicos ncp | D36: ='Output - 3 dígitos'!E58 -> 576636871 | E36: ='Output - 3 dígitos'!F58 -> 24903372 | F36: ='Output - 3 dígitos'!G58 -> 0.04318727 | I36: Fabricación de productos de plástico | J36: 0.019644554 | K36: 5.8448241
A37: ='Output - 3 dígitos'!B59 -> 241 | B37: ='Output - 3 dígitos'!C59 -> Industrias bÃ¡sicas de hierro y acero | C37: Industrias básicas de hierro y acero | D37: ='Output - 3 dígitos'!E59 -> 470760252 | E37: ='Output - 3 dígitos'!F59 -> 2015159 | F37: ='Output - 3 dígitos'!G59 -> 0.0042806481 | I37: Fabricación de productos elaborados de metal ncp | J37: 0.019127709 | K37: 5.8527869
A38: ='Output - 3 dígitos'!B60 -> 242 | B38: ='Output - 3 dígitos'!C60 -> FabricaciÃ³n de productos primarios de metales preciosos y metales no ferrosos | C38: Fabricación de productos primarios de metales preciosos y metales no ferrosos | D38: ='Output - 3 dígitos'!E60 -> 238815019 | E38: ='Output - 3 dígitos'!F60 -> 278630 | F38: ='Output - 3 dígitos'!G60 -> 0.0011667189 | I38: Aserrado y cepillado de madera | J38: 0.018155729 | K38: 1.1174345
... A71: ='Output - 3 dígitos'!B93 -> 329 | B71: ='Output - 3 dígitos'!C93 -> Industrias manufactureras ncp | C71: Industrias manufactureras ncp | D71: ='Output - 3 dígitos'!E93 -> 348542911 | E71: ='Output - 3 dígitos'!F93 -> 4724691 | F71: ='Output - 3 dígitos'!G93 -> 0.01355555 | I71: Fabricación de armas y municiones | J71: 0 | K71: 0
I72: 0 | J72: 0 | K72: 0
I73: 0 | J73: 0 | K73: 0
I74: 0 | J74: 0 | K74: 0
I75: 0 | J75: 0 | K75: 0
I76: 0 | J76: 0 | K76: 0
I77: 0 | J77: 0 | K77: 0
I78: 0 | J78: 0 | K78: 0
I79: 0 | J79: 0 | K79: 0
I80: 0 | J80: 0 | K80: 0
I81: 0 | J81: 0 | K81: 0
I82: 0 | J82: 0 | K82: 0
I83: 0 | J83: 0 | K83: 0
...

Sheet Sectores ARCA
C1: Sectores ARCA | D1: Clasificación Sectores CEU
A2: 11 | B2: =LEFT(C2,3) -> 011 | C2: 011. Cultivos temporales | D2: Agricultura, ganadería y silvicultura
A3: 12 | B3: =LEFT(C3,3) -> 012 | C3: 012. Cultivos perennes | D3: Agricultura, ganadería y silvicultura
A4: 13 | B4: =LEFT(C4,3) -> 013 | C4: 013. Producción de semillas y de otras formas de propagación de cultivos agrícolas | D4: Agricultura, ganadería y silvicultura
A5: 14 | B5: =LEFT(C5,3) -> 014 | C5: 014. Cría de animales | D5: Agricultura, ganadería y silvicultura
A6: 16 | B6: =LEFT(C6,3) -> 016 | C6: 016. Servicios de apoyo agrícolas y pecuarios | D6: Agricultura, ganadería y silvicultura
A7: 17 | B7: =LEFT(C7,3) -> 017 | C7: 017. Caza, repoblación de animales de caza y servicios de apoyo | D7: Agricultura, ganadería y silvicultura
A8: 21 | B8: =LEFT(C8,3) -> 021 | C8: 021. Silvicultura | D8: Agricultura, ganadería y silvicultura
A9: 22 | B9: =LEFT(C9,3) -> 022 | C9: 022. Extracción de productos forestales | D9: Agricultura, ganadería y silvicultura
A10: 24 | B10: =LEFT(C10,3) -> 024 | C10: 024. Servicios de apoyo a la silvicultura | D10: Agricultura, ganadería y silvicultura
A11: 31 | B11: =LEFT(C11,3) -> 031 | C11: 031. Pesca y servicios de apoyo | D11: Pesca
A12: 32 | B12: =LEFT(C12,3) -> 032 | C12: 032. Explotación de criaderos de peces, granjas piscícolas y otros frutos acuáticos (acuicultura) | D12: Pesca
A13: 51 | B13: =LEFT(C13,3) -> 051 | C13: 051. Extracción y aglomeración de carbón | D13: Minería, petróleo y gas
... A224: 960 | B224: =LEFT(C224,3) -> 960 | C224: 960. Servicios personales n.c.p. | D224: Otras actividades de servicios comunitarios, sociales y personales

Sheet INPUT
A1: CLAE 3 | B1: saldo_total (miles de $) | C1: saldo_irregular (miles de $) | D1: tasa_mora
A2: 0 | B2: 62541791564 | C2: 6854484094 | D2: 0.10959846
A3: 0 | B3: 574496028 | C3: 105219837 | D3: 0.18315155
A4: 11 | B4: 6368816432 | C4: 170103112 | D4: 0.026708748
A5: 11 | B5: 2627575 | C5: 115789 | D5: 0.044066868
A6: 12 | B6: 614364343 | C6: 20850754 | D6: 0.033938744
A7: 12 | B7: 482422 | C7: 0 | D7: 0
A8: 13 | B8: 610326960 | C8: 9382330 | D8: 0.015372629
A9: 13 | B9: 56972 | C9: 18655 | D9: 0.32744155
A10: 14 | B10: 2748779585 | C10: 69568184 | D10: 0.025308753
A11: 14 | B11: 666876 | C11: 226523 | D11: 0.33967784
A12: 16 | B12: 1165155534 | C12: 60071354 | D12: 0.051556511
A13: 16 | B13: 294287 | C13: 0 | D13: 0
... A143: 322 | B143: 1973309 | C143: 10913 | D143: 0.0055303047
A144: 322 | B144: 0 | C144: 0
A145: 323 | B145: 4039011 | C145: 167688 | D145: 0.041517094
A146: 324 | B146: 4662430 | C146: 59315 | D146: 0.012721907
A147: 329 | B147: 348211311 | C147: 4724691 | D147: 0.013568459
A148: 329 | B148: 331600 | C148: 0 | D148: 0
A149: 331 | B149: 59372526 | C149: 1886751 | D149: 0.031778183
A150: 331 | B150: 58443 | C150: 0 | D150: 0
A151: 332 | B151: 8948962 | C151: 331271 | D151: 0.037017813
A152: 332 | B152: 88482 | C152: 0 | D152: 0
A153: 351 | B153: 2677664311 | C153: 1737919 | D153: 0.0006490429
A154: 351 | B154: 44073 | C154: 0 | D154: 0
A155: 352 | B155: 251049036 | C155: 2832694 | D155: 0.011283429
A156: 353 | B156: 1910083 | C156: 1416 | D156: 0.00074132904
... A222: 491 | B222: 33839419 | C222: 37345 | D222: 0.0011035946
A223: 491 | B223: 0 | C223: 0
A224: 492 | B224: 2650280576 | C224: 83896344 | D224: 0.031655646
A225: 492 | B225: 6339221 | C225: 18613 | D225: 0.0029361652
A226: 493 | B226: 221130504 | C226: 19440 | D226: 8.7911888e-05
A227: 501 | B227: 13787794 | C227: 47395 | D227: 0.0034374607
A228: 501 | B228: 8073 | C228: 0 | D228: 0
A229: 502 | B229: 7556463 | C229: 474796 | D229: 0.062833101
A230: 511 | B230: 220913234 | C230: 139493 | D230: 0.00063143795
A231: 512 | B231: 8174372 | C231: 132860 | D231: 0.016253236
A232: 512 | B232: 2505725 | C232: 64979 | D232: 0.025932215
A233: 521 | B233: 52043942 | C233: 6260131 | D233: 0.12028549
A234: 521 | B234: 26028 | C234: 6042 | D234: 0.23213462
...
